Workbook

Sheet List
A1: Name | B1: Description | C1: Percentage | D1: Difficulty | E1: Points | F1: Difficulty (nb) | G1: unique_perct_1 | H1: unique_perct_2 | I1: unique_perct_3 | J1: unique_perct_3_done | K1: unique_perct_3_not_done | L1: unique_diff_1 | M1: unique_diff_1_done | N1: unique_diff_1_not_done | O1: Done? | P1: Started with | Q1: Starting conditions | R1: Completion requirements | S1: Notes1 | T1: Notes2 | U1: unique_perct_3_E | V1: unique_perct_3_M | W1: unique_perct_3_H | X1: unique_perct_3_VE | Y1: listed alreeady?
A2: Mayapahit? | B2: Starting as any Mayan country, form Maya and own or have a subject own the island of Java. | C2: 0.002 | D2: H | E2: =(30-C2*100)*VLOOKUP($D2,Calc!$A$1:$C$6,3,FALSE) -> 149 | F2: =VLOOKUP(D2,Calc!$A$1:$B$6,2,FALSE) -> 4 | G2: =C2+F2/10000 -> 0.0024 | H2: =( (CODE(UPPER(LEFT(A2,1)))-64)+(CODE(UPPER(RIGHT(LEFT(A2,2),1)))-64)+(CODE(UPPER(RIGHT(LEFT(A2,3),1)))-64)+(CODE(UPPER(RIGHT(LEFT(A2,4),1)))-64)+(CODE(UPPER(RIGHT(LEFT(A2,5),1)))-64)+(CODE(UPPER(RIGHT(LEFT(A2,6),1)))-64)+(CODE(UPPER(RIGHT(LEFT(A2,7),1)))-64)+(CODE(UPPER(RIGHT(LEFT(A2,8),1)))-64) )/1000000 -> 7.4e-05 | I2: =G2+H2/10 -> 0.0024074 | J2: =IF($O2="","",I2) -> 0.0024074 | K2: =IF($O2="",I2,"") | L2: =F2-I2 -> 3.9975926 | M2: =IF($O2="","",L2) -> 3.9975926 | N2: =IF($O2="",L2,"") | O2: Y | P2: Huastec | Q2: - Religion is Mayan | R2: - Is *or* was Maya - All provinces in the Banten, East Java, Central Java, Surabaya & West Java areas, except Madura (2692): - Province is owned by the player's country *or* its non-tributary subjects | U2: =IF($D2="E",K2,"") | V2: =IF($D2="M",K2,"") | W2: =IF($D2="H",K2,"") | X2: =IF($D2="VE",K2,"") | Y2: =VLOOKUP($A2,Runs!$G:$G,1,FALSE) -> #N/A
A3: Desert Power | B3: Starting as an Arabian Tribe, have the Oasis privilege enacted, and more than 1000 development in the Arabian Region. | C3: 0.002 | D3: H | E3: =(30-C3*100)*VLOOKUP($D3,Calc!$A$1:$C$6,3,FALSE) -> 149 | F3: =VLOOKUP(D3,Calc!$A$1:$B$6,2,FALSE) -> 4 | G3: =C3+F3/10000 -> 0.0024 | H3: =( (CODE(UPPER(LEFT(A3,1)))-64)+(CODE(UPPER(RIGHT(LEFT(A3,2),1)))-64)+(CODE(UPPER(RIGHT(LEFT(A3,3),1)))-64)+(CODE(UPPER(RIGHT(LEFT(A3,4),1)))-64)+(CODE(UPPER(RIGHT(LEFT(A3,5),1)))-64)+(CODE(UPPER(RIGHT(LEFT(A3,6),1)))-64)+(CODE(UPPER(RIGHT(LEFT(A3,7),1)))-64)+(CODE(UPPER(RIGHT(LEFT(A3,8),1)))-64) )/1000000 -> 5.5e-05 | I3: =G3+H3/10 -> 0.0024055 | J3: =IF($O3="","",I3) -> 0.0024055 | K3: =IF($O3="",I3,"") | L3: =F3-I3 -> 3.9975945 | M3: =IF($O3="","",L3) -> 3.9975945 | N3: =IF($O3="",L3,"") | O3: Y | P3: Najd | Q3: - Capital in the Arabia region - Is tribal | R3: - Has granted the Burghers privilege "Oasis Development" - Provinces in the Arabia region that have Desert or Coastal Desert terrain: - Have at least 1000 total development | S3: "Oasis Development" privilege requires the Arabian mission "The Harsh Desert" to be completed. Note that while not mentioned in the description, only the development of Desert and Coastal Desert provinces is counted for the purposes of this achievement. This means that only 44 provinces are valid to develop, requiring a average of 23 (22.7) development in each of these provinces. | U3: =IF($D3="E",K3,"") | V3: =IF($D3="M",K3,"") | W3: =IF($D3="H",K3,"") | X3: =IF($D3="VE",K3,"") | Y3: =VLOOKUP($A3,Runs!$G:$G,1,FALSE) -> #N/A
A4: Legacy of Saint George | B4: As Georgia, have as vassals Genoa, Aragon, England and Trier or their successors, and control Wales. | C4: 0.002 | D4: VH | E4: =(30-C4*100)*VLOOKUP($D4,Calc!$A$1:$C$6,3,FALSE) -> 298 | F4: =VLOOKUP(D4,Calc!$A$1:$B$6,2,FALSE) -> 5 | G4: =C4+F4/10000 -> 0.0025 | H4: =( (CODE(UPPER(LEFT(A4,1)))-64)+(CODE(UPPER(RIGHT(LEFT(A4,2),1)))-64)+(CODE(UPPER(RIGHT(LEFT(A4,3),1)))-64)+(CODE(UPPER(RIGHT(LEFT(A4,4),1)))-64)+(CODE(UPPER(RIGHT(LEFT(A4,5),1)))-64)+(CODE(UPPER(RIGHT(LEFT(A4,6),1)))-64)+(CODE(UPPER(RIGHT(LEFT(A4,7),1)))-64)+(CODE(UPPER(RIGHT(LEFT(A4,8),1)))-64) )/1000000 -> 3.6e-05 | I4: =G4+H4/10 -> 0.0025036 | J4: =IF($O4="","",I4) | K4: =IF($O4="",I4,"") -> 0.0025036 | L4: =F4-I4 -> 4.9974964 | M4: =IF($O4="","",L4) | N4: =IF($O4="",L4,"") -> 4.9974964 | R4: - Is Georgia - Has the following countries (or countries formed by them) as vassals: - - Genoa - Aragon - England - Trier - All provinces in the Wales area: - Are owned by the country or its non-tributary subjects | S4: If one of the countries forms another country(e.g. England forms Great Britain), the new country can be vassalized to get the achievement. If one of the countries dies, care must be taken that the cores don't expire, especially for Trier which is not the primary tag of its culture. | U4: =IF($D4="E",K4,"") | V4: =IF($D4="M",K4,"") | W4: =IF($D4="H",K4,"") | X4: =IF($D4="VE",K4,"") | Y4: =VLOOKUP($A4,Runs!$G:$G,1,FALSE) -> Legacy of Saint George
A5: From Frankfurt to the Andes | B5: Starting as Frankfurt, form Jerusalem, and then form the Inca while owning Mallorca. | C5: 0.002 | D5: VH | E5: =(30-C5*100)*VLOOKUP($D5,Calc!$A$1:$C$6,3,FALSE) -> 298 | F5: =VLOOKUP(D5,Calc!$A$1:$B$6,2,FALSE) -> 5 | G5: =C5+F5/10000 -> 0.0025 | H5: =( (CODE(UPPER(LEFT(A5,1)))-64)+(CODE(UPPER(RIGHT(LEFT(A5,2),1)))-64)+(CODE(UPPER(RIGHT(LEFT(A5,3),1)))-64)+(CODE(UPPER(RIGHT(LEFT(A5,4),1)))-64)+(CODE(UPPER(RIGHT(LEFT(A5,5),1)))-64)+(CODE(UPPER(RIGHT(LEFT(A5,6),1)))-64)+(CODE(UPPER(RIGHT(LEFT(A5,7),1)))-64)+(CODE(UPPER(RIGHT(LEFT(A5,8),1)))-64) )/1000000 -> 4.5e-05 | I5: =G5+H5/10 -> 0.0025045 | J5: =IF($O5="","",I5) -> 0.0025045 | K5: =IF($O5="",I5,"") | L5: =F5-I5 -> 4.9974955 | M5: =IF($O5="","",L5) -> 4.9974955 | N5: =IF($O5="",L5,"") | O5: Y | P5: Frankfurt | Q5: Playing as Frankfurt | R5: - Was Frankfurt - Was Jerusalem - Is Inca - Own Mallorca (333) | S5: - Hardest part of this achievement is finding and fulfilling conditions for different tag formation. - To form Jerusalem, you need to get into coring range of Jerusalem area (vassalize an Italian minor and conquer a province next to it), own and state Jerusalem area, move capital to Arabia, Egypt or Mashriq and switch from Republic to Monarchy. And this has to be done before the Age of Reformation ends, because Frankfurt can't form Jerusalem later. - To form Inca you need to move your capital to the New World, own cores on required provinces, culture shift to Andean culture and change your religion to a pagan faith via rebels. - Switching to play as a released vassal will invalidate the achievement. | U5: =IF($D5="E",K5,"") | V5: =IF($D5="M",K5,"") | W5: =IF($D5="H",K5,"") | X5: =IF($D5="VE",K5,"") | Y5: =VLOOKUP($A5,Runs!$G:$G,1,FALSE) -> From Frankfurt to the Andes
A6: Timurizz | B6: Starting as the Timurids, have 75 prestige, and 5 allies with 100 Trust and 150 opinion. | C6: 0.003 | D6: E | E6: =(30-C6*100)*VLOOKUP($D6,Calc!$A$1:$C$6,3,FALSE) -> 29.7 | F6: =VLOOKUP(D6,Calc!$A$1:$B$6,2,FALSE) -> 2 | G6: =C6+F6/10000 -> 0.0032 | H6: =( (CODE(UPPER(LEFT(A6,1)))-64)+(CODE(UPPER(RIGHT(LEFT(A6,2),1)))-64)+(CODE(UPPER(RIGHT(LEFT(A6,3),1)))-64)+(CODE(UPPER(RIGHT(LEFT(A6,4),1)))-64)+(CODE(UPPER(RIGHT(LEFT(A6,5),1)))-64)+(CODE(UPPER(RIGHT(LEFT(A6,6),1)))-64)+(CODE(UPPER(RIGHT(LEFT(A6,7),1)))-64)+(CODE(UPPER(RIGHT(LEFT(A6,8),1)))-64) )/1000000 -> 0.000142 | I6: =G6+H6/10 -> 0.0032142 | J6: =IF($O6="","",I6) | K6: =IF($O6="",I6,"") -> 0.0032142 | L6: =F6-I6 -> 1.9967858 | M6: =IF($O6="","",L6) | N6: =IF($O6="",L6,"") -> 1.9967858 | Q6: - Is Timurids | R6: - Prestige is at least *+75* - Has at least 5 allies with 100 trust which have at least *+150* opinion of our country | S6: The allies which have the trust have to be the same allies which have the opinion Trust can be gained by honoring calls to arms or by using the *Influence nation* interaction as a great power, or with The Cossacks or Leviathan by trading favors for trust. If neither The Cossacks nor Leviathan are active, trust with allies grows slowly over time. | U6: =IF($D6="E",K6,"") -> 0.0032142 | V6: =IF($D6="M",K6,"") | W6: =IF($D6="H",K6,"") | X6: =IF($D6="VE",K6,"") | Y6: =VLOOKUP($A6,Runs!$G:$G,1,FALSE) -> Timurizz
A7: Ultimate Military | B7: As Songhai, have Prussia and Nepal as marches! | C7: 0.003 | D7: H | E7: =(30-C7*100)*VLOOKUP($D7,Calc!$A$1:$C$6,3,FALSE) -> 148.5 | F7: =VLOOKUP(D7,Calc!$A$1:$B$6,2,FALSE) -> 4 | G7: =C7+F7/10000 -> 0.0034 | H7: =( (CODE(UPPER(LEFT(A7,1)))-64)+(CODE(UPPER(RIGHT(LEFT(A7,2),1)))-64)+(CODE(UPPER(RIGHT(LEFT(A7,3),1)))-64)+(CODE(UPPER(RIGHT(LEFT(A7,4),1)))-64)+(CODE(UPPER(RIGHT(LEFT(A7,5),1)))-64)+(CODE(UPPER(RIGHT(LEFT(A7,6),1)))-64)+(CODE(UPPER(RIGHT(LEFT(A7,7),1)))-64)+(CODE(UPPER(RIGHT(LEFT(A7,8),1)))-64) )/1000000 -> 0.000101 | I7: =G7+H7/10 -> 0.0034101 | J7: =IF($O7="","",I7) -> 0.0034101 | K7: =IF($O7="",I7,"") | L7: =F7-I7 -> 3.9965899 | M7: =IF($O7="","",L7) -> 3.9965899 | N7: =IF($O7="",L7,"") | O7: Y | P7: Songhai | Q7: Playing as Songhai | R7: - Is Songhai - Have Prussia*and*Nepal as marches. | S7: This achievement is only visible if the Origins DLC is active, but it is possible to get the achievement without that DLC. Songhai has a strong starting position, the main difficulty is making sure both Prussia and Nepal exist. Note that only Prussia can be formed by a subject nation, so you are better off giving a Nepali minor the required provinces by calling them to war as ally before subjugating them. | U7: =IF($D7="E",K7,"") | V7: =IF($D7="M",K7,"") | W7: =IF($D7="H",K7,"") | X7: =IF($D7="VE",K7,"") | Y7: =VLOOKUP($A7,Runs!$G:$G,1,FALSE) -> Ultimate Military
A8: Triple the Rome | B8: As Russia, be the Emperor of China and the HRE. | C8: 0.003 | D8: H | E8: =(30-C8*100)*VLOOKUP($D8,Calc!$A$1:$C$6,3,FALSE) -> 148.5 | F8: =VLOOKUP(D8,Calc!$A$1:$B$6,2,FALSE) -> 4 | G8: =C8+F8/10000 -> 0.0034 | H8: =( (CODE(UPPER(LEFT(A8,1)))-64)+(CODE(UPPER(RIGHT(LEFT(A8,2),1)))-64)+(CODE(UPPER(RIGHT(LEFT(A8,3),1)))-64)+(CODE(UPPER(RIGHT(LEFT(A8,4),1)))-64)+(CODE(UPPER(RIGHT(LEFT(A8,5),1)))-64)+(CODE(UPPER(RIGHT(LEFT(A8,6),1)))-64)+(CODE(UPPER(RIGHT(LEFT(A8,7),1)))-64)+(CODE(UPPER(RIGHT(LEFT(A8,8),1)))-64) )/1000000 -> 6.8e-05 | I8: =G8+H8/10 -> 0.0034068 | J8: =IF($O8="","",I8) -> 0.0034068 | K8: =IF($O8="",I8,"") | L8: =F8-I8 -> 3.9965932 | M8: =IF($O8="","",L8) -> 3.9965932 | N8: =IF($O8="",L8,"") | O8: Y | P8: Oirat | R8: - Is Russia - Is Emperor of China - Is the emperor of the Holy Roman Empire | S8: To be Emperor of China, you must be in the Pagan or Eastern religion group, whilst to be the HRE Emperor, you generally must be Catholic unless Protestants won the league war, or sometimes other Christian denominations given specific circumstances (see League war), so a religion switch will be necessary to complete the achievement. Switching to a non-Christian religion as HRE Emperor will cause the emperorship to be lost unless the Erbkaisertum reform has been passed, while changing religion as Emperor of China allows you to retain the title. As such, it may be easiest to start as an atypical nation to form Russia such as Oirat, which starts off as Tengri and can use horde mechanics to relatively easily expand into the territories needed to form Russia. It is recommended to not seize the mandate until the needed provinces are conquered since seizing the mandate will change your government to Celestial Empire and disable horde mechanics. At this point, culture shift to Muscovite, Novgorodian or Ryazanian culture and form Russia once you hit admin tech 10. At some point you will need to conquer a Catholic province, perhaps from the Scandinavian or the Baltic regions, which will allow you to convert to Catholic via rebels. After seizing the Mandate of Heaven, convert to Catholicism, then ally or vassalize enough HRE electors to get yourself elected Holy Roman Emperor. | U8: =IF($D8="E",K8,"") | V8: =IF($D8="M",K8,"") | W8: =IF($D8="H",K8,"") | X8: =IF($D8="VE",K8,"") | Y8: =VLOOKUP($A8,Runs!$G:$G,1,FALSE) -> Triple the Rome
A9: The Zoro-Austrians | B9: Starting as Austria, convert to Zoroastrianism, and complete the Persian Zoroastrian missions. | C9: 0.003 | D9: H | E9: =(30-C9*100)*VLOOKUP($D9,Calc!$A$1:$C$6,3,FALSE) -> 148.5 | F9: =VLOOKUP(D9,Calc!$A$1:$B$6,2,FALSE) -> 4 | G9: =C9+F9/10000 -> 0.0034 | H9: =( (CODE(UPPER(LEFT(A9,1)))-64)+(CODE(UPPER(RIGHT(LEFT(A9,2),1)))-64)+(CODE(UPPER(RIGHT(LEFT(A9,3),1)))-64)+(CODE(UPPER(RIGHT(LEFT(A9,4),1)))-64)+(CODE(UPPER(RIGHT(LEFT(A9,5),1)))-64)+(CODE(UPPER(RIGHT(LEFT(A9,6),1)))-64)+(CODE(UPPER(RIGHT(LEFT(A9,7),1)))-64)+(CODE(UPPER(RIGHT(LEFT(A9,8),1)))-64) )/1000000 -> 7.5e-05 | I9: =G9+H9/10 -> 0.0034075 | J9: =IF($O9="","",I9) | K9: =IF($O9="",I9,"") -> 0.0034075 | L9: =F9-I9 -> 3.9965925 | M9: =IF($O9="","",L9) | N9: =IF($O9="",L9,"") -> 3.9965925 | Q9: Is Austria | R9: - Is Persia*or*Eranshahr - Has completed the mission A New Eranshahr mission - Has completed the An Asha Empire mission | U9: =IF($D9="E",K9,"") | V9: =IF($D9="M",K9,"") | W9: =IF($D9="H",K9,"") -> 0.0034075 | X9: =IF($D9="VE",K9,"") | Y9: =VLOOKUP($A9,Runs!$G:$G,1,FALSE) -> The Zoro-Austrians
A10: The Freest Man in the World | B10: Ensure that no colonized province in the world produces slaves while having the War Against the World Doctrine government reform enacted. | C10: 0.003 | D10: H | E10: =(30-C10*100)*VLOOKUP($D10,Calc!$A$1:$C$6,3,FALSE) -> 148.5 | F10: =VLOOKUP(D10,Calc!$A$1:$B$6,2,FALSE) -> 4 | G10: =C10+F10/10000 -> 0.0034 | H10: =( (CODE(UPPER(LEFT(A10,1)))-64)+(CODE(UPPER(RIGHT(LEFT(A10,2),1)))-64)+(CODE(UPPER(RIGHT(LEFT(A10,3),1)))-64)+(CODE(UPPER(RIGHT(LEFT(A10,4),1)))-64)+(CODE(UPPER(RIGHT(LEFT(A10,5),1)))-64)+(CODE(UPPER(RIGHT(LEFT(A10,6),1)))-64)+(CODE(UPPER(RIGHT(LEFT(A10,7),1)))-64)+(CODE(UPPER(RIGHT(LEFT(A10,8),1)))-64) )/1000000 -> 3.5e-05 | I10: =G10+H10/10 -> 0.0034035 | J10: =IF($O10="","",I10) | K10: =IF($O10="",I10,"") -> 0.0034035 | L10: =F10-I10 -> 3.9965965 | M10: =IF($O10="","",L10) | N10: =IF($O10="",L10,"") -> 3.9965965 | R10: - Has enacted the Pirate Republic government reform - Has enacted the War Against the World Doctrine government reform - No fully colonized province in the world produces slaves | S10: Almost all slave provinces are on the African continent (except Azov). Palembang has a quick event which converts them into pirate republic, but they are Hindu and have mediocre ideas. An easier way is to start as Pasai and hoist the black flag: Pasai has better starting provinces, better ideas, and is Muslim, which makes alliance and AE easier. Alternatively, Gotland also becomes a pirate nation through event. Azov and the Ivory Coast are areas of contention with slaves which need to be rushed to asap. Kilwa has the best starting location and missions in Africa. Complete Prepare the Invasion mission to secure five provinces in Madagascar. Move Kilwa's capital to Zanzibar or Madagascar. Give the remaining provinces to Sofala and release the vassal, then Hoist the Black Flag Can be done easily by releasing and playing as Cornwall after you conquer all slave provinces and abolish slavery, e.g. as England/Great Britain, because Cornwall's pirate event requires just 3 ships privateering. Maghrebi nation such as Tunis can sell non coastal provinces to meet the requirements, an alliance with the Ottomans and a proximity to Genoa help gaining Azov early in the game. | T10: *or* | U10: =IF($D10="E",K10,"") | V10: =IF($D10="M",K10,"") | W10: =IF($D10="H",K10,"") -> 0.0034035 | X10: =IF($D10="VE",K10,"") | Y10: =VLOOKUP($A10,Runs!$G:$G,1,FALSE) -> The Freest Man in the World
A11: Baborg | B11: As the Mughals, assimilate at least 12 culture groups. | C11: 0.003 | D11: H | E11: =(30-C11*100)*VLOOKUP($D11,Calc!$A$1:$C$6,3,FALSE) -> 148.5 | F11: =VLOOKUP(D11,Calc!$A$1:$B$6,2,FALSE) -> 4 | G11: =C11+F11/10000 -> 0.0034 | H11: =( (CODE(UPPER(LEFT(A11,1)))-64)+(CODE(UPPER(RIGHT(LEFT(A11,2),1)))-64)+(CODE(UPPER(RIGHT(LEFT(A11,3),1)))-64)+(CODE(UPPER(RIGHT(LEFT(A11,4),1)))-64)+(CODE(UPPER(RIGHT(LEFT(A11,5),1)))-64)+(CODE(UPPER(RIGHT(LEFT(A11,6),1)))-64)+(CODE(UPPER(RIGHT(LEFT(A11,7),1)))-64)+(CODE(UPPER(RIGHT(LEFT(A11,8),1)))-64) )/1000000 -> 5.9e-05 | I11: =G11+H11/10 -> 0.0034059 | J11: =IF($O11="","",I11) | K11: =IF($O11="",I11,"") -> 0.0034059 | L11: =F11-I11 -> 3.9965941 | M11: =IF($O11="","",L11) | N11: =IF($O11="",L11,"") -> 3.9965941 | R11: - Is Mughals - Has enacted the Mughal Diwan government reform - Has assimilated at least *12* culture groups | T11: - One of - - - | U11: =IF($D11="E",K11,"") | V11: =IF($D11="M",K11,"") | W11: =IF($D11="H",K11,"") -> 0.0034059 | X11: =IF($D11="VE",K11,"") | Y11: =VLOOKUP($A11,Runs!$G:$G,1,FALSE) -> Baborg
A12: Australia-Hungary | B12: Starting as an Australian tribe unite Australia and subjugate Hungary. | C12: 0.003 | D12: H | E12: =(30-C12*100)*VLOOKUP($D12,Calc!$A$1:$C$6,3,FALSE) -> 148.5 | F12: =VLOOKUP(D12,Calc!$A$1:$B$6,2,FALSE) -> 4 | G12: =C12+F12/10000 -> 0.0034 | H12: =( (CODE(UPPER(LEFT(A12,1)))-64)+(CODE(UPPER(RIGHT(LEFT(A12,2),1)))-64)+(CODE(UPPER(RIGHT(LEFT(A12,3),1)))-64)+(CODE(UPPER(RIGHT(LEFT(A12,4),1)))-64)+(CODE(UPPER(RIGHT(LEFT(A12,5),1)))-64)+(CODE(UPPER(RIGHT(LEFT(A12,6),1)))-64)+(CODE(UPPER(RIGHT(LEFT(A12,7),1)))-64)+(CODE(UPPER(RIGHT(LEFT(A12,8),1)))-64) )/1000000 -> 0.000101 | I12: =G12+H12/10 -> 0.0034101 | J12: =IF($O12="","",I12) | K12: =IF($O12="",I12,"") -> 0.0034101 | L12: =F12-I12 -> 3.9965899 | M12: =IF($O12="","",L12) | N12: =IF($O12="",L12,"") -> 3.9965899 | Q12: Playing as one of the following countries: - Australia - Tiwi - Larrakia - Yolngu - Yanuwa - Awngthim - Kamilaroi - Mianjin - Eora - Kulin - Kaurna - Palawa - Wurundjeri - Nyoongah - Malgana | R12: - Hungary is a vassal of this country - Owns all provinces in the Australia region. - Is one of the following countries: - Australia - Tiwi - Larrakia - Yolngu - Yanuwa - Awngthim - Kamilaroi - Mianjin - Eora - Kulin - Kaurna - Palawa - Wurundjeri - Nyoongah - Malgana | S12: Forming a federation will make the achievement much harder as your nation tag will change in the process. One possible way to circumvent this is becoming a steppe horde through government reforms, which changes the technology group to nomadic and allows you to form Australia, but becoming a horde in this way is only possible as a migratory tribe. | U12: =IF($D12="E",K12,"") | V12: =IF($D12="M",K12,"") | W12: =IF($D12="H",K12,"") -> 0.0034101 | X12: =IF($D12="VE",K12,"") | Y12: =VLOOKUP($A12,Runs!$G:$G,1,FALSE) -> Australia-Hungary
A13: Mehmet's Ambition | B13: Starting as The Ottomans, own or have Core Eyalets own all the provinces required to form the Roman Empire before 1500. | C13: 0.003 | D13: I | E13: =(30-C13*100)*VLOOKUP($D13,Calc!$A$1:$C$6,3,FALSE) -> 891 | F13: =VLOOKUP(D13,Calc!$A$1:$B$6,2,FALSE) -> 6 | G13: =C13+F13/10000 -> 0.0036 | H13: =( (CODE(UPPER(LEFT(A13,1)))-64)+(CODE(UPPER(RIGHT(LEFT(A13,2),1)))-64)+(CODE(UPPER(RIGHT(LEFT(A13,3),1)))-64)+(CODE(UPPER(RIGHT(LEFT(A13,4),1)))-64)+(CODE(UPPER(RIGHT(LEFT(A13,5),1)))-64)+(CODE(UPPER(RIGHT(LEFT(A13,6),1)))-64)+(CODE(UPPER(RIGHT(LEFT(A13,7),1)))-64)+(CODE(UPPER(RIGHT(LEFT(A13,8),1)))-64) )/1000000 -> 5.8e-05 | I13: =G13+H13/10 -> 0.0036058 | J13: =IF($O13="","",I13) | K13: =IF($O13="",I13,"") -> 0.0036058 | L13: =F13-I13 -> 5.9963942 | M13: =IF($O13="","",L13) | N13: =IF($O13="",L13,"") -> 5.9963942 | Q13: Playing as the Ottomans | R13: - The year is before 1500 - 425 of the following provinces are owned by this country or a subject of type Core Eyalet: Needed provinces to form the Roman Empire | U13: =IF($D13="E",K13,"") | V13: =IF($D13="M",K13,"") | W13: =IF($D13="H",K13,"") | X13: =IF($D13="VE",K13,"") | Y13: =VLOOKUP($A13,Runs!$G:$G,1,FALSE) -> Mehmet's Ambition
A14: The Hungarian Games | B14: Starting as Hungary, win 23 battles with the Black Army against at least 12 different countries. | C14: 0.003 | D14: M | E14: =(30-C14*100)*VLOOKUP($D14,Calc!$A$1:$C$6,3,FALSE) -> 74.25 | F14: =VLOOKUP(D14,Calc!$A$1:$B$6,2,FALSE) -> 3 | G14: =C14+F14/10000 -> 0.0033 | H14: =( (CODE(UPPER(LEFT(A14,1)))-64)+(CODE(UPPER(RIGHT(LEFT(A14,2),1)))-64)+(CODE(UPPER(RIGHT(LEFT(A14,3),1)))-64)+(CODE(UPPER(RIGHT(LEFT(A14,4),1)))-64)+(CODE(UPPER(RIGHT(LEFT(A14,5),1)))-64)+(CODE(UPPER(RIGHT(LEFT(A14,6),1)))-64)+(CODE(UPPER(RIGHT(LEFT(A14,7),1)))-64)+(CODE(UPPER(RIGHT(LEFT(A14,8),1)))-64) )/1000000 -> 5.1e-05 | I14: =G14+H14/10 -> 0.0033051 | J14: =IF($O14="","",I14) -> 0.0033051 | K14: =IF($O14="",I14,"") | L14: =F14-I14 -> 2.9966949 | M14: =IF($O14="","",L14) -> 2.9966949 | N14: =IF($O14="",L14,"") | O14: Y | P14: Hungary | Q14: - Is Hungary | R14: - Any hired mercenary company: - Is *“Black Army”* - Is *“Black Army Reserves”* - Has won at least *23* battles with these mercenary companies. - For each enemy country, only a maximum of *3* battles are counted | S14: If there are multiple countries on the same side in the battle, only the country which is first in the tag order counts. Doesn't count battles fought when rented out as condottieri. The *“Black Army”* can be unlocked in the following ways, some of which also unlock the *“Black Army Reserves”*: | U14: =IF($D14="E",K14,"") | V14: =IF($D14="M",K14,"") | W14: =IF($D14="H",K14,"") | X14: =IF($D14="VE",K14,"") | Y14: =VLOOKUP($A14,Runs!$G:$G,1,FALSE) -> #N/A
A15: It's all coming together | B15: Complete the Incan mission tree (Sunset invasion missions excluded). | C15: 0.003 | D15: M | E15: =(30-C15*100)*VLOOKUP($D15,Calc!$A$1:$C$6,3,FALSE) -> 74.25 | F15: =VLOOKUP(D15,Calc!$A$1:$B$6,2,FALSE) -> 3 | G15: =C15+F15/10000 -> 0.0033 | H15: =( (CODE(UPPER(LEFT(A15,1)))-64)+(CODE(UPPER(RIGHT(LEFT(A15,2),1)))-64)+(CODE(UPPER(RIGHT(LEFT(A15,3),1)))-64)+(CODE(UPPER(RIGHT(LEFT(A15,4),1)))-64)+(CODE(UPPER(RIGHT(LEFT(A15,5),1)))-64)+(CODE(UPPER(RIGHT(LEFT(A15,6),1)))-64)+(CODE(UPPER(RIGHT(LEFT(A15,7),1)))-64)+(CODE(UPPER(RIGHT(LEFT(A15,8),1)))-64) )/1000000 -> 1.6e-05 | I15: =G15+H15/10 -> 0.0033016 | J15: =IF($O15="","",I15) -> 0.0033016 | K15: =IF($O15="",I15,"") | L15: =F15-I15 -> 2.9966984 | M15: =IF($O15="","",L15) -> 2.9966984 | N15: =IF($O15="",L15,"") | O15: Y | P15: Frankfurt | Q15: - Is *not* playing with a Random New World | R15: Has completed the following missions: - *“Rule of the Sun”* - *“Contact the Oracle”* - *“Defeat the Wanka”* - *“Our Chimuan Rivals”* - *“The Ground Shaker”* - *“Conquer Cajamarca”* - *“Take Over Quito”* - *“Defy the Qollans”* - *“Seize Southern Fringes”* - *“Recruit the Chanka”* - *“Seize the Chincha”* - *“Down the Altiplano”* - *“Promote Runasimi”* - *“Development of the Mitma”* - *“Awka Kamayuq”* - *“The Big Ears”* - *“The Zeq'e System”* - *“The Oracle of Pachacamac”* - *“Four Quarters Together”* - *“The Qollqas”* - *“Construct New Kallanka”* - *“The Solar Cult”* - *“Reform Religion”* - *“Temples to Viracocha”* - *“Imperial Infrastructure”* - *“Qhapaq Ñan”* - *“Imperial Frontiers”* - *“Incan Terracing”* - *“Idols of our Subjects”* - *“Among the Mountaintops”* - *“Navel of the Universe”* - *“Haucaypata”* - *“Collect the Mita”* - *“Sweat of the Sun”* - *“Tears of the Moon”* - *“Renovate Cuzco”* - *“Secondary Capital”* - *“Incan Weaving”* - *“Expand into the Jungle”* - *“Recruit Bowmen”* | U15: =IF($D15="E",K15,"") | V15: =IF($D15="M",K15,"") | W15: =IF($D15="H",K15,"") | X15: =IF($D15="VE",K15,"") | Y15: =VLOOKUP($A15,Runs!$G:$G,1,FALSE) -> It's all coming together
A16: Hanukkah Mutapa | B16: Starting as Mutapa, convert to Judaism and celebrate a festival. | C16: 0.003 | D16: M | E16: =(30-C16*100)*VLOOKUP($D16,Calc!$A$1:$C$6,3,FALSE) -> 74.25 | F16: =VLOOKUP(D16,Calc!$A$1:$B$6,2,FALSE) -> 3 | G16: =C16+F16/10000 -> 0.0033 | H16: =( (CODE(UPPER(LEFT(A16,1)))-64)+(CODE(UPPER(RIGHT(LEFT(A16,2),1)))-64)+(CODE(UPPER(RIGHT(LEFT(A16,3),1)))-64)+(CODE(UPPER(RIGHT(LEFT(A16,4),1)))-64)+(CODE(UPPER(RIGHT(LEFT(A16,5),1)))-64)+(CODE(UPPER(RIGHT(LEFT(A16,6),1)))-64)+(CODE(UPPER(RIGHT(LEFT(A16,7),1)))-64)+(CODE(UPPER(RIGHT(LEFT(A16,8),1)))-64) )/1000000 -> 7.5e-05 | I16: =G16+H16/10 -> 0.0033075 | J16: =IF($O16="","",I16) -> 0.0033075 | K16: =IF($O16="",I16,"") | L16: =F16-I16 -> 2.9966925 | M16: =IF($O16="","",L16) -> 2.9966925 | N16: =IF($O16="",L16,"") | O16: Y | P16: Mutapa | Q16: Playing as Mutapa | R16: - Religion is Jewish - Has used the Jewish religion action *“Celebrate Festival”* | S16: This achievement is misspelled as *“Hannukah Mutapa”* in the steam version of the game. At the start of the game the 2 only Jewish provinces are in Ethiopia, due to Ethiopia's missions the AI will always pick the option to temporarily accept Jewish religion, giving you 25 years to take them. Mutapa's gold mines should allow you to go over force limit and quickly declare a war of conquest against Kilwa despite the technology disadvantage. With additional 3 gold mines in Butua after annexing vassal Butua and conquering Sofala and Kilwa even more mercenaries over force limit can be paid. Focus on military mana to not fall further behind Ethiopia and nations lying in the way to the jewish provinces. | U16: =IF($D16="E",K16,"") | V16: =IF($D16="M",K16,"") | W16: =IF($D16="H",K16,"") | X16: =IF($D16="VE",K16,"") | Y16: =VLOOKUP($A16,Runs!$G:$G,1,FALSE) -> Hanukkah Mutapa
A17: The Eagle flies alone | B17: Starting as Hisn Kayfa, reach a forcelimit of 500k. | C17: 0.003 | D17: VH | E17: =(30-C17*100)*VLOOKUP($D17,Calc!$A$1:$C$6,3,FALSE) -> 297 | F17: =VLOOKUP(D17,Calc!$A$1:$B$6,2,FALSE) -> 5 | G17: =C17+F17/10000 -> 0.0035 | H17: =( (CODE(UPPER(LEFT(A17,1)))-64)+(CODE(UPPER(RIGHT(LEFT(A17,2),1)))-64)+(CODE(UPPER(RIGHT(LEFT(A17,3),1)))-64)+(CODE(UPPER(RIGHT(LEFT(A17,4),1)))-64)+(CODE(UPPER(RIGHT(LEFT(A17,5),1)))-64)+(CODE(UPPER(RIGHT(LEFT(A17,6),1)))-64)+(CODE(UPPER(RIGHT(LEFT(A17,7),1)))-64)+(CODE(UPPER(RIGHT(LEFT(A17,8),1)))-64) )/1000000 -> 2.6e-05 | I17: =G17+H17/10 -> 0.0035026 | J17: =IF($O17="","",I17) -> 0.0035026 | K17: =IF($O17="",I17,"") | L17: =F17-I17 -> 4.9964974 | M17: =IF($O17="","",L17) -> 4.9964974 | N17: =IF($O17="",L17,"") | O17: Y | P17: Hisn Kayfa | Q17: - Is Hisn Kayfa | R17: - Land force limit is at least 500 | U17: =IF($D17="E",K17,"") | V17: =IF($D17="M",K17,"") | W17: =IF($D17="H",K17,"") | X17: =IF($D17="VE",K17,"") | Y17: =VLOOKUP($A17,Runs!$G:$G,1,FALSE) -> #N/A
A18: Quizquiz Pro Quo | B18: As Quizquiz, have your capital in the Anjou province. | C18: 0.003 | D18: VH | E18: =(30-C18*100)*VLOOKUP($D18,Calc!$A$1:$C$6,3,FALSE) -> 297 | F18: =VLOOKUP(D18,Calc!$A$1:$B$6,2,FALSE) -> 5 | G18: =C18+F18/10000 -> 0.0035 | H18: =( (CODE(UPPER(LEFT(A18,1)))-64)+(CODE(UPPER(RIGHT(LEFT(A18,2),1)))-64)+(CODE(UPPER(RIGHT(LEFT(A18,3),1)))-64)+(CODE(UPPER(RIGHT(LEFT(A18,4),1)))-64)+(CODE(UPPER(RIGHT(LEFT(A18,5),1)))-64)+(CODE(UPPER(RIGHT(LEFT(A18,6),1)))-64)+(CODE(UPPER(RIGHT(LEFT(A18,7),1)))-64)+(CODE(UPPER(RIGHT(LEFT(A18,8),1)))-64) )/1000000 -> 0.000146 | I18: =G18+H18/10 -> 0.0035146 | J18: =IF($O18="","",I18) -> 0.0035146 | K18: =IF($O18="",I18,"") | L18: =F18-I18 -> 4.9964854 | M18: =IF($O18="","",L18) -> 4.9964854 | N18: =IF($O18="",L18,"") | O18: Y | P18: Quizquiz | Q18: - Playing as Quizquiz - *Not* using a random New World | R18: - Is Quizquiz - Capital is Anjou (178) | S18: This achievement is only visible if the Leviathan DLC is active, but it can be achieved even without the DLC. | U18: =IF($D18="E",K18,"") | V18: =IF($D18="M",K18,"") | W18: =IF($D18="H",K18,"") | X18: =IF($D18="VE",K18,"") | Y18: =VLOOKUP($A18,Runs!$G:$G,1,FALSE) -> Quizquiz Pro Quo
A19: Mets Hayk | B19: Starting as Karabakh, own, core, and convert to Coptic the borders of Great Armenia. | C19: 0.003 | D19: VH | E19: =(30-C19*100)*VLOOKUP($D19,Calc!$A$1:$C$6,3,FALSE) -> 297 | F19: =VLOOKUP(D19,Calc!$A$1:$B$6,2,FALSE) -> 5 | G19: =C19+F19/10000 -> 0.0035 | H19: =( (CODE(UPPER(LEFT(A19,1)))-64)+(CODE(UPPER(RIGHT(LEFT(A19,2),1)))-64)+(CODE(UPPER(RIGHT(LEFT(A19,3),1)))-64)+(CODE(UPPER(RIGHT(LEFT(A19,4),1)))-64)+(CODE(UPPER(RIGHT(LEFT(A19,5),1)))-64)+(CODE(UPPER(RIGHT(LEFT(A19,6),1)))-64)+(CODE(UPPER(RIGHT(LEFT(A19,7),1)))-64)+(CODE(UPPER(RIGHT(LEFT(A19,8),1)))-64) )/1000000 -> 5.9e-05 | I19: =G19+H19/10 -> 0.0035059 | J19: =IF($O19="","",I19) -> 0.0035059 | K19: =IF($O19="",I19,"") | L19: =F19-I19 -> 4.9964941 | M19: =IF($O19="","",L19) -> 4.9964941 | N19: =IF($O19="",L19,"") | O19: Y | P19: Karabakh | Q19: - Playing as Karabakh | R19: - Religion is Coptic - Owns core provinces following the Coptic faith: - - Erzurum (331) - Yerevan (419) - Melikates (2202) - Nakhchivan (2205) - Erzincan (2305) - Van (2307) - Mush (2306) - Bayazid (2306) - Adana (327) 1 province in each of the following areas is owned, cored, and follows the Coptic faith: - - Azerbaijan - Shahrizor - Al Jazira - Dulkadir - Aleppo - Syria - Syrian Desert | S19: If you can get Mamluks to support your independence, the first war is relatively easy. Once you've grown moderately, try to get European allies as soon as possible to help taking provinces from Ottomans and Mamluks. | U19: =IF($D19="E",K19,"") | V19: =IF($D19="M",K19,"") | W19: =IF($D19="H",K19,"") | X19: =IF($D19="VE",K19,"") | Y19: =VLOOKUP($A19,Runs!$G:$G,1,FALSE) -> #N/A
A20: Crossing the Finnish Line | B20: Release and play as Finland in 1444 and have a direct land connection to the Cape while your capital is in Nyland/Uusimaa. | C20: 0.003 | D20: VH | E20: =(30-C20*100)*VLOOKUP($D20,Calc!$A$1:$C$6,3,FALSE) -> 297 | F20: =VLOOKUP(D20,Calc!$A$1:$B$6,2,FALSE) -> 5 | G20: =C20+F20/10000 -> 0.0035 | H20: =( (CODE(UPPER(LEFT(A20,1)))-64)+(CODE(UPPER(RIGHT(LEFT(A20,2),1)))-64)+(CODE(UPPER(RIGHT(LEFT(A20,3),1)))-64)+(CODE(UPPER(RIGHT(LEFT(A20,4),1)))-64)+(CODE(UPPER(RIGHT(LEFT(A20,5),1)))-64)+(CODE(UPPER(RIGHT(LEFT(A20,6),1)))-64)+(CODE(UPPER(RIGHT(LEFT(A20,7),1)))-64)+(CODE(UPPER(RIGHT(LEFT(A20,8),1)))-64) )/1000000 -> 0.000104 | I20: =G20+H20/10 -> 0.0035104 | J20: =IF($O20="","",I20) -> 0.0035104 | K20: =IF($O20="",I20,"") | L20: =F20-I20 -> 4.9964896 | M20: =IF($O20="","",L20) -> 4.9964896 | N20: =IF($O20="",L20,"") | O20: Y | P20: Sweden | Q20: Playing as Sweden | R20: - Finland has been released in 1444 - Is *or* was Finland - Capital is Nyland(28) - Owns Cape(1177) - There exists a land connection of owned provinces between the capital and Cape(1177) | S20: The land connection can go over strait crossings (it is recommended to avoid taking Suez as to not anger the Ottomans). Finland must be released in 1444, but you do not have to play as them in 1444. Consider making them a vassal, feeding them the provinces required, annexing them, the releasing and playing as them after annexing them. This gives you access to the Sweden mission tree and power base to work with. | U20: =IF($D20="E",K20,"") | V20: =IF($D20="M",K20,"") | W20: =IF($D20="H",K20,"") | X20: =IF($D20="VE",K20,"") | Y20: =VLOOKUP($A20,Runs!$G:$G,1,FALSE) -> #N/A
A21: All Blue | B21: As Portugal, all of Europe is owned by you or blue European countries that exist in 1444. | C21: 0.003 | D21: VH | E21: =(30-C21*100)*VLOOKUP($D21,Calc!$A$1:$C$6,3,FALSE) -> 297 | F21: =VLOOKUP(D21,Calc!$A$1:$B$6,2,FALSE) -> 5 | G21: =C21+F21/10000 -> 0.0035 | H21: =( (CODE(UPPER(LEFT(A21,1)))-64)+(CODE(UPPER(RIGHT(LEFT(A21,2),1)))-64)+(CODE(UPPER(RIGHT(LEFT(A21,3),1)))-64)+(CODE(UPPER(RIGHT(LEFT(A21,4),1)))-64)+(CODE(UPPER(RIGHT(LEFT(A21,5),1)))-64)+(CODE(UPPER(RIGHT(LEFT(A21,6),1)))-64)+(CODE(UPPER(RIGHT(LEFT(A21,7),1)))-64)+(CODE(UPPER(RIGHT(LEFT(A21,8),1)))-64) )/1000000 -> 3.3e-05 | I21: =G21+H21/10 -> 0.0035033 | J21: =IF($O21="","",I21) -> 0.0035033 | K21: =IF($O21="",I21,"") | L21: =F21-I21 -> 4.9964967 | M21: =IF($O21="","",L21) -> 4.9964967 | N21: =IF($O21="",L21,"") | O21: Y | P21: Portugal | Q21: Playing as Portugal | R21: - Is Portugal - All provinces in Europe are owned by one of the following countries: - Portugal - Avaria - Bavaria - Bourbonnais - Bremen - Dithmarschen - Dortmund - Flanders - France - Glogow - Herzegovina - Hesse - Imereti - Ingolstadt - Karaman - Landshut - Lorraine - Mecklenburg - Munich - Naxos - Norway - Odoyev - Perugia - Provence - Prussia - Saluzzo - Sardinia-Piedmont - Sweden - The Knights - The Palatinate - Thuringia - Trebizond - Tyrconnell - Urbino - Venice | S21: Note that Bavaria, Prussia and Sardinia-Piedmont count even though they don't exist in 1444. Make sure that none of the blue countries fulfill the conditions to form something which is not allowed. | U21: =IF($D21="E",K21,"") | V21: =IF($D21="M",K21,"") | W21: =IF($D21="H",K21,"") | X21: =IF($D21="VE",K21,"") | Y21: =VLOOKUP($A21,Runs!$G:$G,1,FALSE) -> #N/A
A22: Let It Go! | B22: Starting as Norway, have your capital in the Canada region while not owning any province in Scandinavia and not playing as a released subject. | C22: 0.004 | D22: E | E22: =(30-C22*100)*VLOOKUP($D22,Calc!$A$1:$C$6,3,FALSE) -> 29.6 | F22: =VLOOKUP(D22,Calc!$A$1:$B$6,2,FALSE) -> 2 | G22: =C22+F22/10000 -> 0.0042 | H22: =( (CODE(UPPER(LEFT(A22,1)))-64)+(CODE(UPPER(RIGHT(LEFT(A22,2),1)))-64)+(CODE(UPPER(RIGHT(LEFT(A22,3),1)))-64)+(CODE(UPPER(RIGHT(LEFT(A22,4),1)))-64)+(CODE(UPPER(RIGHT(LEFT(A22,5),1)))-64)+(CODE(UPPER(RIGHT(LEFT(A22,6),1)))-64)+(CODE(UPPER(RIGHT(LEFT(A22,7),1)))-64)+(CODE(UPPER(RIGHT(LEFT(A22,8),1)))-64) )/1000000 -> 9e-06 | I22: =G22+H22/10 -> 0.0042009 | J22: =IF($O22="","",I22) -> 0.0042009 | K22: =IF($O22="",I22,"") | L22: =F22-I22 -> 1.9957991 | M22: =IF($O22="","",L22) -> 1.9957991 | N22: =IF($O22="",L22,"") | O22: Y | P22: Norway | Q22: Playing as Norway | R22: - *Not* playing as a released vassal - Capital is in the Canada region - Owns no province in the Scandinavia region | S22: Forming countries is allowed, but playing as a released colonial nation or switching to a different country is not allowed. The easiest way to be rid of provinces in Europe is to release Sápmi and Iceland as subjects, giving them all other provinces in Europe other than your capital. At that point, moving your capital into America is allowed, and then giving away the last European province should complete the achievement. | U22: =IF($D22="E",K22,"") | V22: =IF($D22="M",K22,"") | W22: =IF($D22="H",K22,"") | X22: =IF($D22="VE",K22,"") | Y22: =VLOOKUP($A22,Runs!$G:$G,1,FALSE) -> #N/A
A23: Breadbasket of the World | B23: As the Mamluks, export grain to every continent at least once. | C23: 0.004 | D23: E | E23: =(30-C23*100)*VLOOKUP($D23,Calc!$A$1:$C$6,3,FALSE) -> 29.6 | F23: =VLOOKUP(D23,Calc!$A$1:$B$6,2,FALSE) -> 2 | G23: =C23+F23/10000 -> 0.0042 | H23: =( (CODE(UPPER(LEFT(A23,1)))-64)+(CODE(UPPER(RIGHT(LEFT(A23,2),1)))-64)+(CODE(UPPER(RIGHT(LEFT(A23,3),1)))-64)+(CODE(UPPER(RIGHT(LEFT(A23,4),1)))-64)+(CODE(UPPER(RIGHT(LEFT(A23,5),1)))-64)+(CODE(UPPER(RIGHT(LEFT(A23,6),1)))-64)+(CODE(UPPER(RIGHT(LEFT(A23,7),1)))-64)+(CODE(UPPER(RIGHT(LEFT(A23,8),1)))-64) )/1000000 -> 5.2e-05 | I23: =G23+H23/10 -> 0.0042052 | J23: =IF($O23="","",I23) -> 0.0042052 | K23: =IF($O23="",I23,"") | L23: =F23-I23 -> 1.9957948 | M23: =IF($O23="","",L23) -> 1.9957948 | N23: =IF($O23="",L23,"") | O23: Y | P23: Mamluks | R23: - Is *or* was the Mamluks - Has used the "Export Grain" diplomatic action on at least one country on each of the following continents: - - Europe - Oceania - North America - South America - Africa - Asia | S23: The country's continent is determined based on the location of its capital. To use "Export grain", the target must be a subject or ally of the Mamluks. This can be an issue in the colonial regions. Its thus recommended to colonize yourself. | U23: =IF($D23="E",K23,"") | V23: =IF($D23="M",K23,"") | W23: =IF($D23="H",K23,"") | X23: =IF($D23="VE",K23,"") | Y23: =VLOOKUP($A23,Runs!$G:$G,1,FALSE) -> Breadbasket of the World
A24: Veritas Vincit | B24: Starting as Bohemia, make Hussite the official faith of the Empire and become the Emperor. | C24: 0.004 | D24: H | E24: =(30-C24*100)*VLOOKUP($D24,Calc!$A$1:$C$6,3,FALSE) -> 148 | F24: =VLOOKUP(D24,Calc!$A$1:$B$6,2,FALSE) -> 4 | G24: =C24+F24/10000 -> 0.0044 | H24: =( (CODE(UPPER(LEFT(A24,1)))-64)+(CODE(UPPER(RIGHT(LEFT(A24,2),1)))-64)+(CODE(UPPER(RIGHT(LEFT(A24,3),1)))-64)+(CODE(UPPER(RIGHT(LEFT(A24,4),1)))-64)+(CODE(UPPER(RIGHT(LEFT(A24,5),1)))-64)+(CODE(UPPER(RIGHT(LEFT(A24,6),1)))-64)+(CODE(UPPER(RIGHT(LEFT(A24,7),1)))-64)+(CODE(UPPER(RIGHT(LEFT(A24,8),1)))-64) )/1000000 -> 6.2e-05 | I24: =G24+H24/10 -> 0.0044062 | J24: =IF($O24="","",I24) -> 0.0044062 | K24: =IF($O24="",I24,"") | L24: =F24-I24 -> 3.9955938 | M24: =IF($O24="","",L24) -> 3.9955938 | N24: =IF($O24="",L24,"") | O24: Y | P24: Bohemia | Q24: - Is Bohemia | R24: - Is the Holy Roman Emperor - The Holy Roman Empire's official religion is Hussite - The religion of the Holy Roman Empire is fixed | S24: Hussite can become the official religion in the imperial incident "*The Hussite Protest*", which gets triggered if hussite countries own at least 80% as many HRE provinces as non-hussite countries when the event *The Evangelical Union is Victorious* happens. | U24: =IF($D24="E",K24,"") | V24: =IF($D24="M",K24,"") | W24: =IF($D24="H",K24,"") | X24: =IF($D24="VE",K24,"") | Y24: =VLOOKUP($A24,Runs!$G:$G,1,FALSE) -> #N/A
A25: Purify the Temple | B25: Starting as Riga, enact the Salvific Plutocracy government reform and raid the heretic church of Rome. | C25: 0.004 | D25: H | E25: =(30-C25*100)*VLOOKUP($D25,Calc!$A$1:$C$6,3,FALSE) -> 148 | F25: =VLOOKUP(D25,Calc!$A$1:$B$6,2,FALSE) -> 4 | G25: =C25+F25/10000 -> 0.0044 | H25: =( (CODE(UPPER(LEFT(A25,1)))-64)+(CODE(UPPER(RIGHT(LEFT(A25,2),1)))-64)+(CODE(UPPER(RIGHT(LEFT(A25,3),1)))-64)+(CODE(UPPER(RIGHT(LEFT(A25,4),1)))-64)+(CODE(UPPER(RIGHT(LEFT(A25,5),1)))-64)+(CODE(UPPER(RIGHT(LEFT(A25,6),1)))-64)+(CODE(UPPER(RIGHT(LEFT(A25,7),1)))-64)+(CODE(UPPER(RIGHT(LEFT(A25,8),1)))-64) )/1000000 -> 8.3e-05 | I25: =G25+H25/10 -> 0.0044083 | J25: =IF($O25="","",I25) -> 0.0044083 | K25: =IF($O25="",I25,"") | L25: =F25-I25 -> 3.9955917 | M25: =IF($O25="","",L25) -> 3.9955917 | N25: =IF($O25="",L25,"") | O25: Y | P25: Riga | Q25: Playing as Riga | R25: - Has enacted the Salvific Plutocracy government reform - Raided the province Roma (118) with the peace term *“Raid Heretic Churches”* | S25: *“Raid Heretic Churches”* always selects Roma (118) as long as it has a Church or Cathedral. You need to convert to another Christian religion to enact Salvific Plutocracy. *“Raid Heretic Churches”* can also be chosen for secondary war participants. | U25: =IF($D25="E",K25,"") | V25: =IF($D25="M",K25,"") | W25: =IF($D25="H",K25,"") | X25: =IF($D25="VE",K25,"") | Y25: =VLOOKUP($A25,Runs!$G:$G,1,FALSE) -> #N/A
A26: One nation to rule them all | B26: As Saruhan, have at least 9 loyal vassals with at least 100 development each. | C26: 0.004 | D26: H | E26: =(30-C26*100)*VLOOKUP($D26,Calc!$A$1:$C$6,3,FALSE) -> 148 | F26: =VLOOKUP(D26,Calc!$A$1:$B$6,2,FALSE) -> 4 | G26: =C26+F26/10000 -> 0.0044 | H26: =( (CODE(UPPER(LEFT(A26,1)))-64)+(CODE(UPPER(RIGHT(LEFT(A26,2),1)))-64)+(CODE(UPPER(RIGHT(LEFT(A26,3),1)))-64)+(CODE(UPPER(RIGHT(LEFT(A26,4),1)))-64)+(CODE(UPPER(RIGHT(LEFT(A26,5),1)))-64)+(CODE(UPPER(RIGHT(LEFT(A26,6),1)))-64)+(CODE(UPPER(RIGHT(LEFT(A26,7),1)))-64)+(CODE(UPPER(RIGHT(LEFT(A26,8),1)))-64) )/1000000 -> 4.6e-05 | I26: =G26+H26/10 -> 0.0044046 | J26: =IF($O26="","",I26) | K26: =IF($O26="",I26,"") -> 0.0044046 | L26: =F26-I26 -> 3.9955954 | M26: =IF($O26="","",L26) | N26: =IF($O26="",L26,"") -> 3.9955954 | R26: - Is Saruhan - 9 countries fulfill the following conditions: - is a vassal of Saruhan - has less than *50%* liberty desire - has at least *100* development | S26: Saruhan's core starts under the control of the Ottomans. Suggested strategy: expand rapidly as you normally would with the Ottomans until you have ~1200 development. Then, plan to release-and-play as Saruhan, taking most of Otto's lands. To do this, you will need to release Saruhan as vassal, wait 10 years, start to annex (to designate cores), feed it land, finalize annexation, and then release-and-play. You can cheese the release-and-play by feeding past the point of loyalty and then applying all available annexation cost reductions (Acquire Subjects mission, Influence idea, Amirs privilege, as well as any possible Policies). Make sure you wait until the last day of the month to do this, or else annexation progress will drop and you will be unable to proceed. As long as your annexation progress is above 100 on the month tick, it won't matter if liberty desire is over 50%. Once you have reannexed, you will be able to release-and-play. Ideally you will then own almost all Ottoman lands, making independence relatively easy to pursue. From there, you need to obtain 9 loyal vassals (NOT marches, NOT client states) with 100+ development. Rather than directly subjugating enemies to meet the vassal count, it is suggested that the player conquer and then release vassals; this avoids the forced vassalization malus. To help reduce liberty desire and thus total development needed, choose the relevant policies, and be sure to get the Splendor abilities in the Age of Revolutions (Anti-Revolutionary Zeal + Loyal Subjects). Upon release, you will no longer have the Ottoman government form, and should choose Iqta. Then on your goverment tab choose Lenient Taxation, which provides another Liberty Desire reduction. Note that during the feeding of Saruhan and following your transition to playing as them, the Ottomans will likely be severely weakened and thus open to attack. Keep this in mind, perhaps securing treaties in advance or locking in allies (though too many allies for Otto will make subsequent independence harder). Ideally you will be able to secure independence support from a rival. | U26: =IF($D26="E",K26,"") | V26: =IF($D26="M",K26,"") | W26: =IF($D26="H",K26,"") -> 0.0044046 | X26: =IF($D26="VE",K26,"") | Y26: =VLOOKUP($A26,Runs!$G:$G,1,FALSE) -> One nation to rule them all
A27: New, New Deli | B27: As Deli, have your capital in the Delhi province. | C27: 0.004 | D27: H | E27: =(30-C27*100)*VLOOKUP($D27,Calc!$A$1:$C$6,3,FALSE) -> 148 | F27: =VLOOKUP(D27,Calc!$A$1:$B$6,2,FALSE) -> 4 | G27: =C27+F27/10000 -> 0.0044 | H27: =( (CODE(UPPER(LEFT(A27,1)))-64)+(CODE(UPPER(RIGHT(LEFT(A27,2),1)))-64)+(CODE(UPPER(RIGHT(LEFT(A27,3),1)))-64)+(CODE(UPPER(RIGHT(LEFT(A27,4),1)))-64)+(CODE(UPPER(RIGHT(LEFT(A27,5),1)))-64)+(CODE(UPPER(RIGHT(LEFT(A27,6),1)))-64)+(CODE(UPPER(RIGHT(LEFT(A27,7),1)))-64)+(CODE(UPPER(RIGHT(LEFT(A27,8),1)))-64) )/1000000 -> 3.2e-05 | I27: =G27+H27/10 -> 0.0044032 | J27: =IF($O27="","",I27) | K27: =IF($O27="",I27,"") -> 0.0044032 | L27: =F27-I27 -> 3.9955968 | M27: =IF($O27="","",L27) | N27: =IF($O27="",L27,"") -> 3.9955968 | Q27: - Playing as Deli - *Not* using a random New World | R27: - Is Deli - Capital is Delhi (522) | S27: This achievement is only visible if the Leviathan DLC is active, but it can be achieved even without the DLC. Can be done in 5–10 years, depending on RNG. Broadly: get as many allies as you can to deter coalition. Vassalize an OPM adjacent to Delhi, preferably Garhwal or Sirmur to even the AE. Then conquer Delhi (and some needed to connect). Give every other territories to vassals, or sell them to other countries. In a war, lose your capital Riau, after that Delhi will be the new capital. | U27: =IF($D27="E",K27,"") | V27: =IF($D27="M",K27,"") | W27: =IF($D27="H",K27,"") -> 0.0044032 | X27: =IF($D27="VE",K27,"") | Y27: =VLOOKUP($A27,Runs!$G:$G,1,FALSE) -> New, New Deli
A28: Knights of the Caribbean | B28: Starting as the Knights, own the Caribbean and every island in the Mediterranean. (Colonies are NOT allowed) | C28: 0.004 | D28: H | E28: =(30-C28*100)*VLOOKUP($D28,Calc!$A$1:$C$6,3,FALSE) -> 148 | F28: =VLOOKUP(D28,Calc!$A$1:$B$6,2,FALSE) -> 4 | G28: =C28+F28/10000 -> 0.0044 | H28: =( (CODE(UPPER(LEFT(A28,1)))-64)+(CODE(UPPER(RIGHT(LEFT(A28,2),1)))-64)+(CODE(UPPER(RIGHT(LEFT(A28,3),1)))-64)+(CODE(UPPER(RIGHT(LEFT(A28,4),1)))-64)+(CODE(UPPER(RIGHT(LEFT(A28,5),1)))-64)+(CODE(UPPER(RIGHT(LEFT(A28,6),1)))-64)+(CODE(UPPER(RIGHT(LEFT(A28,7),1)))-64)+(CODE(UPPER(RIGHT(LEFT(A28,8),1)))-64) )/1000000 -> 5.6e-05 | I28: =G28+H28/10 -> 0.0044056 | J28: =IF($O28="","",I28) -> 0.0044056 | K28: =IF($O28="",I28,"") | L28: =F28-I28 -> 3.9955944 | M28: =IF($O28="","",L28) -> 3.9955944 | N28: =IF($O28="",L28,"") | O28: Y | P28: Knights | Q28: Playing as The Knights | R28: - Owns all provinces in the Caribbean region. Owns the following core provinces: - Rhodes (320) - Cyprus (321) - Crete (163) - Naxos (164) - Chios (2348) - Euboea (3003) - Lesbos (4700) - Cephalonia (4698) - Corfu (142) - Syracuse (2982) - Messina (124) - Palermo (125) - Girgenti (4737) - Trapani (4736) - Djerba (2954) - Malta (126) - Sassari (127) - Corsica (1247) - Menorca (4559) - Ibiza (4560) - Mallorca (333) - Venezia (112) - Arborea (4735) - Cagliari (2986) Map of the Mediterranean provinces: The needed mediterranean provinces | S28: Bermuda is also part of the Caribbean region even though it is not part of the Colonial Caribbean colonial region. | U28: =IF($D28="E",K28,"") | V28: =IF($D28="M",K28,"") | W28: =IF($D28="H",K28,"") | X28: =IF($D28="VE",K28,"") | Y28: =VLOOKUP($A28,Runs!$G:$G,1,FALSE) -> #N/A
A29: Fugger Banking | B29: As Augsburg, subsidize 3 Great Powers 20% of their income while having less than 20 provinces. | C29: 0.004 | D29: H | E29: =(30-C29*100)*VLOOKUP($D29,Calc!$A$1:$C$6,3,FALSE) -> 148 | F29: =VLOOKUP(D29,Calc!$A$1:$B$6,2,FALSE) -> 4 | G29: =C29+F29/10000 -> 0.0044 | H29: =( (CODE(UPPER(LEFT(A29,1)))-64)+(CODE(UPPER(RIGHT(LEFT(A29,2),1)))-64)+(CODE(UPPER(RIGHT(LEFT(A29,3),1)))-64)+(CODE(UPPER(RIGHT(LEFT(A29,4),1)))-64)+(CODE(UPPER(RIGHT(LEFT(A29,5),1)))-64)+(CODE(UPPER(RIGHT(LEFT(A29,6),1)))-64)+(CODE(UPPER(RIGHT(LEFT(A29,7),1)))-64)+(CODE(UPPER(RIGHT(LEFT(A29,8),1)))-64) )/1000000 -> 3.4e-05 | I29: =G29+H29/10 -> 0.0044034 | J29: =IF($O29="","",I29) -> 0.0044034 | K29: =IF($O29="",I29,"") | L29: =F29-I29 -> 3.9955966 | M29: =IF($O29="","",L29) -> 3.9955966 | N29: =IF($O29="",L29,"") | O29: Y | P29: Augsburg | Q29: - Playing as Augsburg | R29: - Is Augsburg - less than 20 provinces - Subsidize 3 Great Powers at least 20% of their income. | S29: The subsidies also count as income, so the subsidies have to be 25% of the income before subsidies. The total income can be seen in the Income Comparison page in the ledger. The Country page doesn't show all income sources. You can subsidize up to 50% of your income to each country, which means you need to reach at least half the income of the 3 poorest great powers. A good way to get it quickly is to get a hold of the Inntal or Eger goldmine and to develop it. | U29: =IF($D29="E",K29,"") | V29: =IF($D29="M",K29,"") | W29: =IF($D29="H",K29,"") | X29: =IF($D29="VE",K29,"") | Y29: =VLOOKUP($A29,Runs!$G:$G,1,FALSE) -> #N/A
A30: Almost Prussian Blue | B30: Starting as the Livonian Order, form Livonia and own the territory of the North German Confederation as core provinces. | C30: 0.004 | D30: H | E30: =(30-C30*100)*VLOOKUP($D30,Calc!$A$1:$C$6,3,FALSE) -> 148 | F30: =VLOOKUP(D30,Calc!$A$1:$B$6,2,FALSE) -> 4 | G30: =C30+F30/10000 -> 0.0044 | H30: =( (CODE(UPPER(LEFT(A30,1)))-64)+(CODE(UPPER(RIGHT(LEFT(A30,2),1)))-64)+(CODE(UPPER(RIGHT(LEFT(A30,3),1)))-64)+(CODE(UPPER(RIGHT(LEFT(A30,4),1)))-64)+(CODE(UPPER(RIGHT(LEFT(A30,5),1)))-64)+(CODE(UPPER(RIGHT(LEFT(A30,6),1)))-64)+(CODE(UPPER(RIGHT(LEFT(A30,7),1)))-64)+(CODE(UPPER(RIGHT(LEFT(A30,8),1)))-64) )/1000000 -> 6.4e-05 | I30: =G30+H30/10 -> 0.0044064 | J30: =IF($O30="","",I30) | K30: =IF($O30="",I30,"") -> 0.0044064 | L30: =F30-I30 -> 3.9955936 | M30: =IF($O30="","",L30) | N30: =IF($O30="",L30,"") -> 3.9955936 | Q30: Playing as Livonian Order | R30: - Is Livonia Own and core all the following provinces: - East Prussia area - West Prussia area - Silesia area - North Germany region except the areas Bohemia, Moravia and Erzgebirge - Chelmno (1859) - Inowroclaw (4523) - Gniezno (4526) - Poznan (254) - Notec (2963) - East Frisia (1931) Map of the provinces: | U30: =IF($D30="E",K30,"") | V30: =IF($D30="M",K30,"") | W30: =IF($D30="H",K30,"") -> 0.0044064 | X30: =IF($D30="VE",K30,"") | Y30: =VLOOKUP($A30,Runs!$G:$G,1,FALSE) -> Almost Prussian Blue
A31: Where are the penguins? | B31: As a Malagasy country, unite Madagascar and hold all the most southern provinces of the world. | C31: 0.004 | D31: M | E31: =(30-C31*100)*VLOOKUP($D31,Calc!$A$1:$C$6,3,FALSE) -> 74 | F31: =VLOOKUP(D31,Calc!$A$1:$B$6,2,FALSE) -> 3 | G31: =C31+F31/10000 -> 0.0043 | H31: =( (CODE(UPPER(LEFT(A31,1)))-64)+(CODE(UPPER(RIGHT(LEFT(A31,2),1)))-64)+(CODE(UPPER(RIGHT(LEFT(A31,3),1)))-64)+(CODE(UPPER(RIGHT(LEFT(A31,4),1)))-64)+(CODE(UPPER(RIGHT(LEFT(A31,5),1)))-64)+(CODE(UPPER(RIGHT(LEFT(A31,6),1)))-64)+(CODE(UPPER(RIGHT(LEFT(A31,7),1)))-64)+(CODE(UPPER(RIGHT(LEFT(A31,8),1)))-64) )/1000000 -> 4.6e-05 | I31: =G31+H31/10 -> 0.0043046 | J31: =IF($O31="","",I31) -> 0.0043046 | K31: =IF($O31="",I31,"") | L31: =F31-I31 -> 2.9956954 | M31: =IF($O31="","",L31) -> 2.9956954 | N31: =IF($O31="",L31,"") | O31: Y | P31: Imerina | Q31: *Not* using a random New World Playing as one of the following countries: - Sakalava - Betsimisaraka - Imerina - Mahafaly - Antemoro | R31: Is one of the following countries: - Sakalava - Betsimisaraka - Imerina - Mahafaly - Antemoro Own and core all provinces in the following areas: - Madagascar Highlands - Betsimasaraka - Sakalava - Southern Madagascar Own or have a non-tributary subject own all the following provinces: - Cape (1177) - Swellendam (1179) - Algoa Bay (833) - Xhosa (1180) - Wadjuk (1084) - Minang (2727) - Nukunu (2736) - Kaurna (1086) - Gunditjmara (2735) - Wurundjeri (1087) - Yuin (2734) - Peerapper (4869) - Pyemmairrener (4868) - Paredarerme (1085) - Tharawal (4858) - Ata Whenua (1246) - Timaru (1109) - Kawesqar (783) - Tierra del Fuego (782) - Florida Blanca (2869) - Falklands (1095) - South Georgia (2025) Map of the provinces: | S31: After taking over Madagascar befriend Kilwa to get Feudalism spreading. Take Exploration, then Expansion and colonize the provinces on the Cape of Good Hope. Afterwards focus your attention mostly on the Atlantic islands and South America to get the required provinces before Portugal does, only spreading east when waiting for colonies to finish for reach. Station troops in Australia after the colonial nation forms, otherwise the natives will attack. This achievement is only visible if the Origins DLC is active, but no DLC is needed to complete it. | U31: =IF($D31="E",K31,"") | V31: =IF($D31="M",K31,"") | W31: =IF($D31="H",K31,"") | X31: =IF($D31="VE",K31,"") | Y31: =VLOOKUP($A31,Runs!$G:$G,1,FALSE) -> Where are the penguins?
A32: There Khan only be one! | B32: Starting as a Steppe Horde, ensure there exists no other horde than you in the world. | C32: 0.004 | D32: M | E32: =(30-C32*100)*VLOOKUP($D32,Calc!$A$1:$C$6,3,FALSE) -> 74 | F32: =VLOOKUP(D32,Calc!$A$1:$B$6,2,FALSE) -> 3 | G32: =C32+F32/10000 -> 0.0043 | H32: =( (CODE(UPPER(LEFT(A32,1)))-64)+(CODE(UPPER(RIGHT(LEFT(A32,2),1)))-64)+(CODE(UPPER(RIGHT(LEFT(A32,3),1)))-64)+(CODE(UPPER(RIGHT(LEFT(A32,4),1)))-64)+(CODE(UPPER(RIGHT(LEFT(A32,5),1)))-64)+(CODE(UPPER(RIGHT(LEFT(A32,6),1)))-64)+(CODE(UPPER(RIGHT(LEFT(A32,7),1)))-64)+(CODE(UPPER(RIGHT(LEFT(A32,8),1)))-64) )/1000000 -> 4.3e-05 | I32: =G32+H32/10 -> 0.0043043 | J32: =IF($O32="","",I32) -> 0.0043043 | K32: =IF($O32="",I32,"") | L32: =F32-I32 -> 2.9956957 | M32: =IF($O32="","",L32) -> 2.9956957 | N32: =IF($O32="",L32,"") | O32: Y | P32: Great Horde | Q32: - Has enacted the Steppe Nomads government reform | R32: - This country has enacted one of the following government reforms: - Steppe Nomads - Great Mongol State - No other country has enacted one of the following government reforms: - Steppe Nomads - Great Mongol State - *countries which switched their government type through government reforms (e.g. by enacting The Great Plains call to us) or enacted Become Horde are not counted* | U32: =IF($D32="E",K32,"") | V32: =IF($D32="M",K32,"") | W32: =IF($D32="H",K32,"") | X32: =IF($D32="VE",K32,"") | Y32: =VLOOKUP($A32,Runs!$G:$G,1,FALSE) -> #N/A
A33: Stardust Crusaders | B33: As Japan have the Land of the Christian Sun reform while Palestine and Cairo are Christian under us. | C33: 0.004 | D33: M | E33: =(30-C33*100)*VLOOKUP($D33,Calc!$A$1:$C$6,3,FALSE) -> 74 | F33: =VLOOKUP(D33,Calc!$A$1:$B$6,2,FALSE) -> 3 | G33: =C33+F33/10000 -> 0.0043 | H33: =( (CODE(UPPER(LEFT(A33,1)))-64)+(CODE(UPPER(RIGHT(LEFT(A33,2),1)))-64)+(CODE(UPPER(RIGHT(LEFT(A33,3),1)))-64)+(CODE(UPPER(RIGHT(LEFT(A33,4),1)))-64)+(CODE(UPPER(RIGHT(LEFT(A33,5),1)))-64)+(CODE(UPPER(RIGHT(LEFT(A33,6),1)))-64)+(CODE(UPPER(RIGHT(LEFT(A33,7),1)))-64)+(CODE(UPPER(RIGHT(LEFT(A33,8),1)))-64) )/1000000 -> 0.000122 | I33: =G33+H33/10 -> 0.0043122 | J33: =IF($O33="","",I33) | K33: =IF($O33="",I33,"") -> 0.0043122 | L33: =F33-I33 -> 2.9956878 | M33: =IF($O33="","",L33) | N33: =IF($O33="",L33,"") -> 2.9956878 | R33: - Is Japan - Has enacted the Land of the Christian Sun government reform - The Palestine area and the province Cairo (361) have a Christian religion and are owned by this country | S33: To get the Land of the Christian Sun government reform, it is mandatory to get the open outcome in the incident Spread of Christianity. | U33: =IF($D33="E",K33,"") | V33: =IF($D33="M",K33,"") -> 0.0043122 | W33: =IF($D33="H",K33,"") | X33: =IF($D33="VE",K33,"") | Y33: =VLOOKUP($A33,Runs!$G:$G,1,FALSE) -> Stardust Crusaders
A34: Golden Wind | B34: As Air, make 50 ducats profit per month and have 50% of your income made through gold provinces. | C34: 0.004 | D34: M | E34: =(30-C34*100)*VLOOKUP($D34,Calc!$A$1:$C$6,3,FALSE) -> 74 | F34: =VLOOKUP(D34,Calc!$A$1:$B$6,2,FALSE) -> 3 | G34: =C34+F34/10000 -> 0.0043 | H34: =( (CODE(UPPER(LEFT(A34,1)))-64)+(CODE(UPPER(RIGHT(LEFT(A34,2),1)))-64)+(CODE(UPPER(RIGHT(LEFT(A34,3),1)))-64)+(CODE(UPPER(RIGHT(LEFT(A34,4),1)))-64)+(CODE(UPPER(RIGHT(LEFT(A34,5),1)))-64)+(CODE(UPPER(RIGHT(LEFT(A34,6),1)))-64)+(CODE(UPPER(RIGHT(LEFT(A34,7),1)))-64)+(CODE(UPPER(RIGHT(LEFT(A34,8),1)))-64) )/1000000 -> 4.8e-05 | I34: =G34+H34/10 -> 0.0043048 | J34: =IF($O34="","",I34) -> 0.0043048 | K34: =IF($O34="",I34,"") | L34: =F34-I34 -> 2.9956952 | M34: =IF($O34="","",L34) -> 2.9956952 | N34: =IF($O34="",L34,"") | O34: Y | P34: Air | Q34: Playing as Air | R34: - Is Air - monthly balance is at least *50* - 50% of the monthly income is from gold | S34: This achievement is only visible if the Origins DLC is active, but no DLC is needed to complete it. As Air consider royal marrying Songhai and Mali and improving relations after to get an alliance. Both should start neutral most of the time and are strong allies. After, look for choice targets and build over force limit by hiring a free company. Air starts with a level 2 fort on their capital so rushing smaller enemy capital forts is a viable strategy, no need to take unnecessary battles. You need 50 positive balance, not income. Consider disbanding armies, firing advisors and deleting forts when your income is over 60 ducats, with at least 50% gold income. Almost all expenses can be reduced to near 0 except for state maintenance. To get enough gold income controlling and developing the three gold mines in West Africa should be enough. In 1444 two are owned by Mali and one by Kong. | U34: =IF($D34="E",K34,"") | V34: =IF($D34="M",K34,"") | W34: =IF($D34="H",K34,"") | X34: =IF($D34="VE",K34,"") | Y34: =VLOOKUP($A34,Runs!$G:$G,1,FALSE) -> Golden Wind
A35: Copium Wars | B35: Starting and playing as Ming, own the Britain region. | C35: 0.004 | D35: M | E35: =(30-C35*100)*VLOOKUP($D35,Calc!$A$1:$C$6,3,FALSE) -> 74 | F35: =VLOOKUP(D35,Calc!$A$1:$B$6,2,FALSE) -> 3 | G35: =C35+F35/10000 -> 0.0043 | H35: =( (CODE(UPPER(LEFT(A35,1)))-64)+(CODE(UPPER(RIGHT(LEFT(A35,2),1)))-64)+(CODE(UPPER(RIGHT(LEFT(A35,3),1)))-64)+(CODE(UPPER(RIGHT(LEFT(A35,4),1)))-64)+(CODE(UPPER(RIGHT(LEFT(A35,5),1)))-64)+(CODE(UPPER(RIGHT(LEFT(A35,6),1)))-64)+(CODE(UPPER(RIGHT(LEFT(A35,7),1)))-64)+(CODE(UPPER(RIGHT(LEFT(A35,8),1)))-64) )/1000000 -> 6.8e-05 | I35: =G35+H35/10 -> 0.0043068 | J35: =IF($O35="","",I35) -> 0.0043068 | K35: =IF($O35="",I35,"") | L35: =F35-I35 -> 2.9956932 | M35: =IF($O35="","",L35) -> 2.9956932 | N35: =IF($O35="",L35,"") | O35: Y | P35: Ming | Q35: - Playing as Ming - AI-controlled custom nations are allowed, but they are not required | R35: - Is Ming - Own all provinces in the Britain region Britain region | S35: This is one of only two achievements which allows a custom nation on the map which can't be earned by playing that custom nation. | U35: =IF($D35="E",K35,"") | V35: =IF($D35="M",K35,"") | W35: =IF($D35="H",K35,"") | X35: =IF($D35="VE",K35,"") | Y35: =VLOOKUP($A35,Runs!$G:$G,1,FALSE) -> Copium Wars
A36: Inner Turmoil | B36: Starting as The Isles, own 20 provinces by 1500, none of which are on Islands. | C36: 0.004 | D36: VH | E36: =(30-C36*100)*VLOOKUP($D36,Calc!$A$1:$C$6,3,FALSE) -> 296 | F36: =VLOOKUP(D36,Calc!$A$1:$B$6,2,FALSE) -> 5 | G36: =C36+F36/10000 -> 0.0045 | H36: =( (CODE(UPPER(LEFT(A36,1)))-64)+(CODE(UPPER(RIGHT(LEFT(A36,2),1)))-64)+(CODE(UPPER(RIGHT(LEFT(A36,3),1)))-64)+(CODE(UPPER(RIGHT(LEFT(A36,4),1)))-64)+(CODE(UPPER(RIGHT(LEFT(A36,5),1)))-64)+(CODE(UPPER(RIGHT(LEFT(A36,6),1)))-64)+(CODE(UPPER(RIGHT(LEFT(A36,7),1)))-64)+(CODE(UPPER(RIGHT(LEFT(A36,8),1)))-64) )/1000000 -> 6.9e-05 | I36: =G36+H36/10 -> 0.0045069 | J36: =IF($O36="","",I36) -> 0.0045069 | K36: =IF($O36="",I36,"") | L36: =F36-I36 -> 4.9954931 | M36: =IF($O36="","",L36) -> 4.9954931 | N36: =IF($O36="",L36,"") | O36: Y | P36: The Isles | Q36: - Playing as The Isles - *Not* using a random New World | R36: - The year is before 1500 - owns at least 20 fully colonized provinces(cities) that are *not*on an island | S36: it is allowed to have provinces on islands, but these don't count towards the 20. Islands in the context of this achievement means any province which does not have a land connection to mainland continents, meaning any province in Britain or Ireland will not count. Unfinished colonies also don't count. An easy way to achieve this is to wait until one of the berber nations is without allies and noCB them. You can core Moroccan and Sus provinces with extended range from exploration ideas and the colonial range advisor. From there, you can keep eating North Africa, or go to West Africa. The provinces do not need to be cored. | U36: =IF($D36="E",K36,"") | V36: =IF($D36="M",K36,"") | W36: =IF($D36="H",K36,"") | X36: =IF($D36="VE",K36,"") | Y36: =VLOOKUP($A36,Runs!$G:$G,1,FALSE) -> Inner Turmoil
A37: I don't like sand | B37: Have the most development while owning no province with terrain other than desert or coastal desert. | C37: 0.004 | D37: VH | E37: =(30-C37*100)*VLOOKUP($D37,Calc!$A$1:$C$6,3,FALSE) -> 296 | F37: =VLOOKUP(D37,Calc!$A$1:$B$6,2,FALSE) -> 5 | G37: =C37+F37/10000 -> 0.0045 | H37: =( (CODE(UPPER(LEFT(A37,1)))-64)+(CODE(UPPER(RIGHT(LEFT(A37,2),1)))-64)+(CODE(UPPER(RIGHT(LEFT(A37,3),1)))-64)+(CODE(UPPER(RIGHT(LEFT(A37,4),1)))-64)+(CODE(UPPER(RIGHT(LEFT(A37,5),1)))-64)+(CODE(UPPER(RIGHT(LEFT(A37,6),1)))-64)+(CODE(UPPER(RIGHT(LEFT(A37,7),1)))-64)+(CODE(UPPER(RIGHT(LEFT(A37,8),1)))-64) )/1000000 -> -2.7e-05 | I37: =G37+H37/10 -> 0.0044973 | J37: =IF($O37="","",I37) | K37: =IF($O37="",I37,"") -> 0.0044973 | L37: =F37-I37 -> 4.9955027 | M37: =IF($O37="","",L37) | N37: =IF($O37="",L37,"") -> 4.9955027 | Q37: *Not* using a random New World | R37: - All provinces are either desert or coastal desert - No other country has a higher development than this country All desert and coastal desert provinces | S37: Easiest as Ajuuraan or the Mamluks, because of their national ideas and the "Hydraulic Rights" estate privilege (which reduces the additional cost from developing deserts and coastal desert by half), that is unlocked through a mission in Origins DLC. Forming Arabia (possibly via Yemen to avoid the tech requirement) will unlock the similar "Oasis Development" privilege, which stacks with "Hydraulic Rights" | U37: =IF($D37="E",K37,"") | V37: =IF($D37="M",K37,"") | W37: =IF($D37="H",K37,"") | X37: =IF($D37="VE",K37,"") | Y37: =VLOOKUP($A37,Runs!$G:$G,1,FALSE) -> I don't like sand
